Workbook

Sheet Summary
A1: AI NOC automation (MCP-connector suite) vs NCP R2.0 Test Report - connector coverage
A2: Manual side: NCP R2.0 Test Report.xlsx (Dev's master, read only; file dated 2026-10-05), one sheet per connector. Automation side: the 20 prompts in data/mcp_prompts.xlsx (P01-P20) of the AI-NOC-Automation repo, each graded against the connector's own API. Built 2026-10-06.
A4: 1. Manual testcases per connector, and how many the automation covers
A5: Connector | B5: Manual sheet | C5: Manual testcases | D5: Manual PASS | E5: Manual FAIL | F5: Covered | G5: Partly covered | H5: Gap - can automate | I5: Next phase | J5: Out of scope | K5: Prompt-level testcases | L5: Prompt-level covered (full or part)
A6: Nexus Dashboard (Local MCP) | B6: Nexus agent to support NetOps | C6: =COUNTA(Nexus!$A$2:$A$90) -> 89 | D6: =COUNTIF(Nexus!$D$2:$D$90,"PASS") -> 88 | E6: =COUNTIF(Nexus!$D$2:$D$90,"FAIL") -> 1 | F6: =COUNTIF(Nexus!$F$2:$F$90,"Covered") -> 21 | G6: =COUNTIF(Nexus!$F$2:$F$90,"Partly covered") -> 22 | H6: =COUNTIF(Nexus!$F$2:$F$90,"Gap - can automate") -> 27 | I6: =COUNTIF(Nexus!$F$2:$F$90,"Next phase") -> 0 | J6: =COUNTIF(Nexus!$F$2:$F$90,"Out of scope") -> 19 | K6: =C6-I6-J6 -> 70 | L6: =IF(K6=0,"no prompt-level testcases",(F6+G6)/K6) -> 0.61428571
A7: Catalyst Center (Local MCP) | B7: Local MCP center to Catalyst | C7: =COUNTA(Catalyst!$A$2:$A$26) -> 25 | D7: =COUNTIF(Catalyst!$D$2:$D$26,"PASS") -> 25 | E7: =COUNTIF(Catalyst!$D$2:$D$26,"FAIL") -> 0 | F7: =COUNTIF(Catalyst!$F$2:$F$26,"Covered") -> 0 | G7: =COUNTIF(Catalyst!$F$2:$F$26,"Partly covered") -> 0 | H7: =COUNTIF(Catalyst!$F$2:$F$26,"Gap - can automate") -> 0 | I7: =COUNTIF(Catalyst!$F$2:$F$26,"Next phase") -> 0 | J7: =COUNTIF(Catalyst!$F$2:$F$26,"Out of scope") -> 25 | K7: =C7-I7-J7 -> 0 | L7: =IF(K7=0,"no prompt-level testcases",(F7+G7)/K7) -> no prompt-level testcases
A8: Zabbix | B8: Zabbix-DC | C8: =COUNTA(Zabbix!$A$2:$A$127) -> 126 | D8: =COUNTIF(Zabbix!$D$2:$D$127,"PASS") -> 123 | E8: =COUNTIF(Zabbix!$D$2:$D$127,"FAIL") -> 3 | F8: =COUNTIF(Zabbix!$F$2:$F$127,"Covered") -> 23 | G8: =COUNTIF(Zabbix!$F$2:$F$127,"Partly covered") -> 27 | H8: =COUNTIF(Zabbix!$F$2:$F$127,"Gap - can automate") -> 62 | I8: =COUNTIF(Zabbix!$F$2:$F$127,"Next phase") -> 0 | J8: =COUNTIF(Zabbix!$F$2:$F$127,"Out of scope") -> 14 | K8: =C8-I8-J8 -> 112 | L8: =IF(K8=0,"no prompt-level testcases",(F8+G8)/K8) -> 0.44642857
A9: ONES | B9: AI-NOC-ONES-MCP | C9: =COUNTA('ONES-MCP'!$A$2:$A$65) -> 64 | D9: =COUNTIF('ONES-MCP'!$D$2:$D$65,"PASS") -> 46 | E9: =COUNTIF('ONES-MCP'!$D$2:$D$65,"FAIL") -> 18 | F9: =COUNTIF('ONES-MCP'!$F$2:$F$65,"Covered") -> 5 | G9: =COUNTIF('ONES-MCP'!$F$2:$F$65,"Partly covered") -> 9 | H9: =COUNTIF('ONES-MCP'!$F$2:$F$65,"Gap - can automate") -> 34 | I9: =COUNTIF('ONES-MCP'!$F$2:$F$65,"Next phase") -> 13 | J9: =COUNTIF('ONES-MCP'!$F$2:$F$65,"Out of scope") -> 3 | K9: =C9-I9-J9 -> 48 | L9: =IF(K9=0,"no prompt-level testcases",(F9+G9)/K9) -> 0.29166667
A10: Total | C10: =SUM(C6:C9) -> 304 | D10: =SUM(D6:D9) -> 282 | E10: =SUM(E6:E9) -> 22 | F10: =SUM(F6:F9) -> 49 | G10: =SUM(G6:G9) -> 58 | H10: =SUM(H6:H9) -> 123 | I10: =SUM(I6:I9) -> 13 | J10: =SUM(J6:J9) -> 61 | K10: =SUM(K6:K9) -> 230 | L10: =(F10+G10)/K10 -> 0.46521739
A11: Prompt-level testcases = all testcases minus Next phase and Out of scope (UI, onboarding / container / API-level, security, logs, performance, write actions).
A13: 2. The 20 automated prompts per connector - is there a matching manual testcase?
A14: Connector | B14: Automated prompts | C14: With a manual testcase | D14: No manual testcase
A15: Nexus Dashboard (Local MCP) | B15: =COUNTA('Automation view'!$A$2:$A$21) -> 20 | C15: =B15-D15 -> 13 | D15: =COUNTIF('Automation view'!$C$2:$C$21,"—") -> 7
A16: Catalyst Center (Local MCP) | B16: =COUNTA('Automation view'!$A$2:$A$21) -> 20 | C16: =B16-D16 -> 0 | D16: =COUNTIF('Automation view'!$D$2:$D$21,"—") -> 20
A17: Zabbix | B17: =COUNTA('Automation view'!$A$2:$A$21) -> 20 | C17: =B17-D17 -> 17 | D17: =COUNTIF('Automation view'!$E$2:$E$21,"—") -> 3
A18: ONES | B18: =COUNTA('Automation view'!$A$2:$A$21) -> 20 | C18: =B18-D18 -> 9 | D18: =COUNTIF('Automation view'!$F$2:$F$21,"—") -> 11
A20: 3. What stands out
A21: Catalyst | B21: The manual sheet has 25 testcases and none of them checks chat answers against Catalyst data - they are UI, onboarding, container and API checks. The 20 automated prompts are the only Catalyst data checks. Vishakh's live run found NCP missing a down interface (P14, GigabitEthernet1/0/3 on leaf01) in two chats, and showing only a sample of interface counters (P15) - neither is in the manual sheet (CLAUDE.md §3.10).
A22: Nexus | B22: The manual prompt cases match the automated prompts well (inventory, health, CPU / memory, interfaces, links). The manual sheet adds fabric, anomaly / advisory and cluster prompts that are not automated. Manual #70 '#tag list all switches' is FAIL; the automation smoke on 10.4.5.236 also got a wrong answer ('0 devices', P02, conversation 3012).
A23: Zabbix | B23: Biggest manual set (126). The automation covers inventory, CPU / memory, temperature, PSU, health and interfaces. Not automated: problems, triggers, time windows and charts. Problems and triggers are the easiest to add - the suite already reads Zabbix triggers - and two of the three manual FAILs are there (#99, #101).
A24: ONES | B24: The manual run was on a different ONES MCP connector than the automation (the sheet does not name it; Dev's notes list #ones-37-mcp -> 10.20.0.37; automation uses #ONES-MCP -> 10.4.4.181), so results are not directly comparable. 13 compliance rows belong to the next phase. Alerts cannot be automated yet: the ONES alert APIs fail on both hosts. Protocol, transceiver and service prompts are the main gaps.
A25: All | B25: Manual PASS is the tester's judgement; the automation compares each answer to the source by code. Project Chat is not automated yet (only Admin Chat with #tag).
A27: Coverage values
A28: Covered | B28: An automated prompt checks the same thing against the connector's own data.
A29: Partly covered | B29: Same topic, but the automated check is narrower or wider, or runs in a different chat.
A30: Gap - can automate | B30: A prompt-level test we could add - see the 'Gaps to add' sheet.
A31: Next phase | B31: Planned in the AI NOC compliance / audit use cases, not this suite.
A32: Out of scope | B32: UI (another engineer), onboarding / container / API-level, security, logs, performance, write actions - handled separately.

Sheet Nexus
A1: No | B1: Category | C1: Title (manual testcase) | D1: Manual result | E1: Bug Id | F1: Coverage | G1: Automated prompt(s) | H1: Gap group | I1: Note
A2: 1 | B2: UI | C2: Verify Nexus Dashboard provider displays both Local MCP and Remote MCP tabs | D2: PASS | F2: Out of scope | I2: UI test - UI automation is handled by another engineer.
A3: 2 | B3: UI | C3: Verify the Local MCP tab is accessible and selectable | D3: PASS | F3: Out of scope | I3: UI test - UI automation is handled by another engineer.
A4: 3 | B4: Configuration | C4: Verify a Nexus Local MCP connector can be created with valid host, credentials, optional MCP token and tag | D4: PASS | F4: Out of scope | I4: Connector onboarding / lifecycle - API-level, handled separately (not prompt validation).
A5: 4 | B5: Configuration | C5: Verify connector status changes to Running after successful creation | D5: PASS | F5: Out of scope | I5: Connector onboarding / lifecycle - API-level, handled separately (not prompt validation).
A6: 5 | B6: Configuration | C6: Verify connector type is displayed as MCP after successful onboarding | D6: PASS | F6: Out of scope | I6: UI test - UI automation is handled by another engineer.
A7: 6 | B7: Configuration | C7: Verify the configured connector tag is displayed correctly | D7: PASS | F7: Out of scope | I7: UI test - UI automation is handled by another engineer.
A8: 7 | B8: Configuration | C8: Verify mandatory field validation is displayed when required fields are left blank | D8: PASS | F8: Out of scope | I8: UI test - UI automation is handled by another engineer.
A9: 8 | B9: Configuration | C9: Verify invalid Nexus credentials prevent connector creation | D9: PASS | F9: Out of scope | I9: Connector onboarding / lifecycle - API-level, handled separately (not prompt validation).
A10: 9 | B10: Configuration | C10: Verify connector creation fails gracefully when Nexus Dashboard is unreachable | D10: PASS | F10: Out of scope | I10: Connector onboarding / lifecycle - API-level, handled separately (not prompt validation).
A11: 10 | B11: Container | C11: Verify the ncp-nexus-dashboard-mcp LocalMCP container starts successfully after connector creation | D11: PASS | F11: Out of scope | I11: MCP container lifecycle - platform / API-level, handled separately.
A12: 11 | B12: Container | C12: Verify the LocalMCP entrypoint is used instead of the collector image | D12: PASS | F12: Out of scope | I12: MCP container lifecycle - platform / API-level, handled separately.
A13: 12 | B13: Project | C13: Verify the Nexus LocalMCP connector can be enabled for a project | D13: PASS | F13: Out of scope | I13: Project scoping - API-level, handled separately.
A14: 13 | B14: Project | C14: Verify a new project chat can access the enabled Nexus LocalMCP connector | D14: PASS | F14: Gap - can automate | H14: Project Chat | I14: Project Chat is not automated yet (CLAUDE.md §11 q2, q3).
A15: 14 | B15: Routing | C15: Verify infrastructure queries are routed through the query_nexus tool | D15: PASS | F15: Out of scope | I15: Tool routing (which tool ran) - needs the agent trace; routing checks are handled separately.
A16: 15 | B16: Routing | C16: Verify child tools are invoked correctly for CPU, memory, interface inventory and link details | D16: PASS | F16: Out of scope | I16: Tool routing (which tool ran) - needs the agent trace; routing checks are handled separately.
A17: 16 | B17: Routing | C17: Verify chat does not request set_mcp_connection during normal operations | D17: PASS | F17: Gap - can automate | H17: No credential / MCP-connection request | I17: Can be added as a check on every answer.
A18: 17 | B18: Routing | C18: Verify users are not prompted for Nexus username, password or token during chat queries | D18: PASS | F18: Gap - can automate | H18: No credential / MCP-connection request | I18: Can be added as a check on every answer.
A19: 18 | B19: Project Chat | C19: Verify 'List all switches' returns live Nexus switch inventory | D19: PASS | F19: Partly covered | G19: P01 | I19: Same check runs in Admin Chat with #tag; Project Chat is not automated yet (CLAUDE.md §11 q2, q3).
A20: 19 | B20: Project Chat | C20: Verify unhealthy switches are identified correctly from live Nexus data | D20: PASS | F20: Partly covered | G20: P06 | I20: Same check runs in Admin Chat with #tag; Project Chat is not automated yet (CLAUDE.md §11 q2, q3). Health = Nexus status in the suite; the manual case expects anomaly / advisory info.
A21: 20 | B21: Project Chat | C21: Verify fabric summary is returned for a selected fabric | D21: PASS | F21: Gap - can automate | H21: Nexus fabric prompts
A22: 21 | B22: Project Chat | C22: Verify switches belonging to a selected fabric are listed correctly | D22: PASS | F22: Gap - can automate | H22: Nexus fabric prompts
A23: 22 | B23: Project Chat | C23: Verify CPU and memory status is returned for every switch | D23: PASS | F23: Partly covered | G23: P07, P08 | I23: Same check runs in Admin Chat with #tag; Project Chat is not automated yet (CLAUDE.md §11 q2, q3).
A24: 23 | B24: Project Chat | C24: Verify CPU and memory information is returned for a specific switch | D24: PASS | F24: Partly covered | G24: P09 | I24: Same check runs in Admin Chat with #tag; Project Chat is not automated yet (CLAUDE.md §11 q2, q3).
A25: 24 | B25: Project Chat | C25: Verify switch-by-switch infrastructure summary is generated successfully | D25: PASS | F25: Partly covered | G25: P19 | I25: Same check runs in Admin Chat with #tag; Project Chat is not automated yet (CLAUDE.md §11 q2, q3).
A26: 25 | B26: Project Chat | C26: Verify interface inventory is returned for a selected switch | D26: PASS | F26: Partly covered | G26: P13 | I26: Same check runs in Admin Chat with #tag; Project Chat is not automated yet (CLAUDE.md §11 q2, q3).
A27: 26 | B27: Project Chat | C27: Verify operationally down interfaces are identified correctly | D27: PASS | F27: Partly covered | G27: P14 | I27: Same check runs in Admin Chat with #tag; Project Chat is not automated yet (CLAUDE.md §11 q2, q3).
A28: 27 | B28: Project Chat | C28: Verify interface counters are retrieved successfully for the selected fabric | D28: PASS | F28: Partly covered | G28: P15 | I28: Same check runs in Admin Chat with #tag; Project Chat is not automated yet (CLAUDE.md §11 q2, q3). Manual asks per fabric; automation asks per switch.
A29: 28 | B29: Project Chat | C29: Verify link details are returned for the selected fabric | D29: PASS | F29: Partly covered | G29: P16 | I29: Same check runs in Admin Chat with #tag; Project Chat is not automated yet (CLAUDE.md §11 q2, q3).
A30: 29 | B30: Project Chat | C30: Verify anomaly summary grouped by severity is displayed correctly | D30: PASS | F30: Gap - can automate | H30: Nexus anomalies / advisories
A31: 30 | B31: Project Chat | C31: Verify advisory summary is generated using live Nexus data | D31: PASS | F31: Gap - can automate | H31: Nexus anomalies / advisories
A32: 31 | B32: Admin Chat | C32: Verify Admin Chat successfully accesses the connector using the configured connector tag | D32: PASS | F32: Covered | G32: P01-P20 | I32: Every automated prompt is sent in Admin Chat as '#tag <prompt>'.
A33: 32 | B33: Admin Chat | C33: Verify inventory queries work correctly using #connector-tag | D33: PASS | F33: Covered | G33: P01
A34: 33 | B34: Admin Chat | C34: Verify CPU and memory queries work correctly using #connector-tag | D34: PASS | F34: Covered | G34: P07, P08
A35: 34 | B35: Admin Chat | C35: Verify interface inventory queries work correctly using #connector-tag | D35: PASS | F35: Covered | G35: P13
A36: 35 | B36: Admin Chat | C36: Verify link detail queries work correctly using #connector-tag | D36: PASS | F36: Covered | G36: P16
A37: 36 | B37: Admin Chat | C37: Verify an incorrect connector tag does not access the Nexus LocalMCP connector | D37: PASS | F37: Gap - can automate | H37: Wrong-tag negative prompt | I37: Negative tag case.
A38: 37 | B38: Admin Chat | C38: Verify Admin Chat without a connector tag follows the default routing behavior | D38: PASS | F38: Out of scope | I38: Control case for default routing (the manual sheet itself says it is not pass / fail).
A39: 38 | B39: Inventory | C39: Verify hostname, model, serial number, role and software version are returned for Nexus switches | D39: PASS | F39: Partly covered | G39: P03 | I39: Role is not checked.
A40: 39 | B40: Inventory | C40: Verify switch count and roles are returned correctly for a fabric | D40: PASS | F40: Partly covered | G40: P02 | I40: Count is checked; per fabric and roles are not.
...

Sheet Catalyst
A1: No | B1: Category | C1: Title (manual testcase) | D1: Manual result | E1: Bug Id | F1: Coverage | G1: Automated prompt(s) | H1: Gap group | I1: Note
A2: 1 | B2: UI - Connector Dialog | C2: Verify switching between tabs shows the correct field set per mode without carrying stale values across modes | D2: PASS | F2: Out of scope | I2: UI test - UI automation is handled by another engineer.
A3: 2 | B3: UI - Form Validation | C3: Verify the Connect button stays disabled until Name, Catalyst URI and the selected credential fields are populated | D3: PASS | F3: Out of scope | I3: UI test - UI automation is handled by another engineer.
A4: 3 | B4: UI - Form Validation | C4: Verify the Catalyst URI field accepts a valid https URL and flags malformed input | D4: PASS | F4: Out of scope | I4: UI test - UI automation is handled by another engineer.
A5: 4 | B5: UI - Form Validation | C5: Verify a duplicate connector name is rejected, matching the "use a new connector name" guidance for Local MCP mode | D5: PASS | F5: Out of scope | I5: UI test - UI automation is handled by another engineer.
A6: 5 | B6: UI - Authentication Method | C6: Verify Auth Token is offered as an authentication method and shows a single Auth Token field | D6: PASS | F6: Out of scope | I6: UI test - UI automation is handled by another engineer.
A7: 6 | B7: UI - Authentication Method | C7: Verify selecting Username & Password swaps to User and Password fields with a masked password and a show/hide toggle | D7: PASS | F7: Out of scope | I7: UI test - UI automation is handled by another engineer.
A8: 7 | B8: UI - Authentication Method | C8: Verify switching the authentication method clears the secret entered under the previous method | D8: PASS | E8: https://aviznetworks.atlassian.net/browse/NCP-3762 | F8: Out of scope | I8: UI test - UI automation is handled by another engineer.
A9: 8 | B9: Onboarding - Local MCP Mode | C9: Verify Catalyst Center onboards successfully in Local MCP mode using username and password (recorded happy path) | D9: PASS | F9: Out of scope | I9: Connector onboarding / lifecycle - API-level, handled separately (not prompt validation).
A10: 9 | B10: Connector Lifecycle | C10: Verify connector create, edit and delete for the Catalyst Center Local MCP connector are recorded in the Activity Log | D10: PASS | F10: Out of scope | I10: Activity Log for connector create / edit / delete - API-level, handled separately.
A11: 10 | B11: Onboarding - Local MCP Mode | C11: Verify the success toast and dialog close behaviour, and that the connector list refreshes without a manual reload | D11: PASS | F11: Out of scope | I11: UI test - UI automation is handled by another engineer.
A12: 11 | B12: Connector List & Status | C12: Verify the new Catalyst Center Local MCP row renders the correct Provider Type, Type, Status, Description and timestamps | D12: PASS | F12: Out of scope | I12: UI test - UI automation is handled by another engineer.
A13: 12 | B13: Connector List & Status | C13: Verify the Local MCP row exposes the same row actions as the other MCP connectors (view / edit / delete) | D13: PASS | F13: Out of scope | I13: UI test - UI automation is handled by another engineer.
A14: 13 | B14: MCP Container Lifecycle | C14: Verify a container named ncp-catalyst-center-mcp-* is started on successful Local MCP onboarding | D14: PASS | F14: Out of scope | I14: MCP container lifecycle - platform / API-level, handled separately.
A15: 14 | B15: MCP Container Lifecycle | C15: Verify the MCP container receives the Catalyst Center host and credentials from connector config rather than a hardcoded value | D15: PASS | F15: Out of scope | I15: MCP container lifecycle - platform / API-level, handled separately.
A16: 15 | B16: MCP Container Lifecycle | C16: Verify the MCP container recovers after a restart and the connector Status returns to Running | D16: PASS | F16: Out of scope | I16: MCP container lifecycle - platform / API-level, handled separately.
A17: 16 | B17: MCP Container Lifecycle | C17: Verify deleting the Local MCP connector stops and removes its MCP container | D17: PASS | F17: Out of scope | I17: MCP container lifecycle - platform / API-level, handled separately.
A18: 17 | B18: SSE Endpoint (/mcp/sse:8001) | C18: Verify an MCP client can establish a session against the Catalyst Center MCP server and list its tools | D18: PASS | F18: Out of scope | I18: Direct MCP client session / tool list - API-level, not through chat.
A19: 18 | B19: SSE Endpoint (/mcp/sse:8001) | C19: Verify a Catalyst Center read tool executes through the MCP server and returns real data from the configured CatC | D19: PASS | F19: Out of scope | I19: Direct MCP tool call - API-level. (The 20 automated prompts use the same read tools through chat and check the answers against Catalyst Center's own API.)
A20: 19 | B20: ncp-api Dual-Mode Resolution | C20: Verify ncp-api resolves a LocalMCP-mode Catalyst Center connector to the container SSE endpoint on :8001 /mcp/sse | D20: PASS | F20: Out of scope | I20: ncp-api connector resolution - API-level, handled separately.
... A26: 25 | B26: Zero-Impact / Regression | C26: Verify the pre-existing Catalyst Center API connector is completely unaffected by Local MCP onboarding | D26: PASS | F26: Out of scope | I26: API-mode connector (metrics-DB path) - Automation 2 DC-INVENTORY covers Catalyst on that path.

Sheet Zabbix
A1: No | B1: Category | C1: Title (manual testcase) | D1: Manual result | E1: Bug Id | F1: Coverage | G1: Automated prompt(s) | H1: Gap group | I1: Note
A2: 1 | B2: Zabbix Agent | C2: Zabbix Agent routes infrastructure queries through query_zabbix | D2: PASS | F2: Out of scope | I2: Tool routing (which tool ran) - needs the agent trace; routing checks are handled separately.
A3: 2 | B3: Zabbix Agent | C3: Only supported read-only tools are used for query execution | D3: PASS | F3: Out of scope | I3: Security check - handled separately (API-level).
A4: 3 | B4: Zabbix Agent | C4: Agent never performs write operations on the Zabbix server | D4: PASS | F4: Out of scope | I4: Security check - handled separately (API-level).
A5: 4 | B5: Inventory | C5: List all monitored hosts from Zabbix inventory | D5: PASS | F5: Covered | G5: P01
A6: 5 | B6: Inventory | C6: Retrieve host model information | D6: PASS | F6: Covered | G6: P03, P05
A7: 6 | B7: Inventory | C7: Retrieve serial numbers of monitored devices | D7: PASS | F7: Covered | G7: P03
A8: 7 | B8: Inventory | C8: Retrieve operating system version for monitored devices | D8: PASS | F8: Covered | G8: P03, P04
A9: 8 | B9: Inventory | C9: Retrieve management IP addresses of monitored devices | D9: PASS | F9: Covered | G9: P03
A10: 9 | B10: Inventory | C10: Retrieve hardware vendor information | D10: PASS | F10: Gap - can automate | H10: Zabbix vendors
A11: 10 | B11: Inventory | C11: Retrieve software version of monitored devices | D11: PASS | F11: Covered | G11: P03
A12: 11 | B12: Metrics | C12: Current CPU utilization for a selected device | D12: PASS | F12: Covered | G12: P09
A13: 12 | B13: Metrics | C13: Current memory utilization for a selected device | D13: PASS | F13: Covered | G13: P09
A14: 13 | B14: Metrics | C14: Current temperature metrics | D14: PASS | F14: Covered | G14: P18
A15: 14 | B15: Metrics | C15: Current fan speed metrics | D15: PASS | F15: Partly covered | G15: P17 | I15: Fan status is checked; fan speed is not.
A16: 15 | B16: Metrics | C16: PSU status metrics | D16: PASS | F16: Covered | G16: P17
A17: 16 | B17: Metrics | C17: Uptime metrics | D17: PASS | F17: Gap - can automate | H17: Zabbix extra items
A18: 17 | B18: Metrics | C18: Disk utilization metrics | D18: PASS | F18: Gap - can automate | H18: Zabbix extra items
A19: 18 | B19: Metrics | C19: Min, average, max and latest values for a time window | D19: PASS | F19: Gap - can automate | H19: Time-window prompts
A20: 19 | B20: Health | C20: Complete health snapshot for a selected host | D20: PASS | F20: Partly covered | G20: P19 | I20: Fleet summary is checked; a single-host snapshot is not asked.
A21: 20 | B21: Health | C21: Health snapshot includes metrics, sensors and active problems | D21: PASS | F21: Partly covered | G21: P19 | I21: Problems and sensor detail are not checked.
A22: 21 | B22: Health | C22: Unhealthy devices are identified correctly | D22: PASS | F22: Covered | G22: P06
A23: 22 | B23: Health | C23: Overall fleet health summary | D23: PASS | F23: Covered | G23: P19
A24: 23 | B24: Problems | C24: Active problems are displayed correctly | D24: PASS | F24: Gap - can automate | H24: Zabbix problems
A25: 24 | B25: Problems | C25: Problems grouped by severity | D25: PASS | F25: Gap - can automate | H25: Zabbix problems
A26: 25 | B26: Problems | C26: Problems filtered by host | D26: PASS | F26: Gap - can automate | H26: Zabbix problems
A27: 26 | B27: Problems | C27: Problems filtered by time window | D27: PASS | F27: Gap - can automate | H27: Time-window prompts
A28: 27 | B28: Problems | C28: Acknowledged and unacknowledged problems | D28: PASS | F28: Gap - can automate | H28: Zabbix problems
A29: 28 | B29: Problems | C29: Resolved problems within a selected time window | D29: PASS | F29: Gap - can automate | H29: Time-window prompts
A30: 29 | B30: Triggers | C30: Configured triggers for a selected host | D30: PASS | F30: Gap - can automate | H30: Zabbix triggers
A31: 30 | B31: Triggers | C31: Trigger definitions displayed correctly | D31: PASS | F31: Gap - can automate | H31: Zabbix triggers
A32: 31 | B32: Triggers | C32: Disabled triggers are identified correctly | D32: PASS | F32: Gap - can automate | H32: Zabbix triggers
A33: 32 | B33: Interfaces | C33: Interface inventory for a selected host | D33: PASS | F33: Covered | G33: P13
A34: 33 | B34: Interfaces | C34: Operational status of interfaces | D34: PASS | F34: Covered | G34: P14
A35: 34 | B35: Interfaces | C35: Administrative status of interfaces | D35: PASS | F35: Gap - can automate | H35: Zabbix extra items
A36: 35 | B36: Interfaces | C36: Interface speed and duplex information | D36: PASS | F36: Gap - can automate | H36: Zabbix extra items
A37: 36 | B37: Interfaces | C37: Interface error counters | D37: PASS | F37: Partly covered | G37: P15 | I37: Counters must be shown; values are not compared.
A38: 37 | B38: Interfaces | C38: Interface discard counters | D38: PASS | F38: Partly covered | G38: P15 | I38: Counters must be shown; values are not compared.
A39: 38 | B39: Interfaces | C39: Per-port traffic utilization | D39: PASS | F39: Gap - can automate | H39: Time-window prompts | I39: Traffic values move - needs a time-pinned compare.
A40: 39 | B40: Fleet Analytics | C40: Rank hosts by CPU utilization across the fleet | D40: PASS | F40: Partly covered | G40: P07, P10 | I40: Each host's value and the top host are checked; the full ranking order is not.
...

Sheet ONES-MCP
A1: No | B1: Category | C1: Title (manual testcase) | D1: Manual result | E1: Bug Id | F1: Coverage | G1: Automated prompt(s) | H1: Gap group | I1: Note
A2: 1 | B2: General / Overview | C2: List all devices with hostname and health status | D2: FAIL | E2: NCP-3716 NCP-3717 | F2: Covered | G2: P01, P19 | I2: Manual FAIL.
A3: 2 | B3: General / Overview | C3: How many fabrics are in the inventory? | D3: PASS | F3: Gap - can automate | H3: ONES Fabric Manager (read)
A4: 3 | B4: General / Overview | C4: Show all alerts from the last 24 hours | D4: FAIL | E4: NCP-3718 NCP-3719 | F4: Gap - can automate | H4: ONES alerts
A5: 4 | B5: General / Overview | C5: What is the ONES installation ID? | D5: PASS | F5: Gap - can automate | H5: ONES admin & licences
A6: 5 | B6: General / Overview | C6: List all ONES users | D6: PASS | F6: Gap - can automate | H6: ONES admin & licences
A7: 6 | B7: Alerts | C7: Show alerts for rule <rule-name> | D7: FAIL | E7: NCP-3718 NCP-3719 | F7: Gap - can automate | H7: ONES alerts
A8: 7 | B8: Alerts | C8: What alerts are active on switch <IP>? | D8: FAIL | E8: NCP-3718 NCP-3719 | F8: Gap - can automate | H8: ONES alerts
A9: 8 | B9: Alerts | C9: Show <rule-name> alerts on switch <IP> | D9: FAIL | E9: NCP-3718 NCP-3719 | F9: Gap - can automate | H9: ONES alerts
A10: 9 | B10: Alerts | C10: Get full payload for alert UUID <UUID> | D10: PASS | F10: Gap - can automate | H10: ONES alerts
A11: 10 | B11: Health - Network-wide | C11: Health overview of all devices | D11: PASS | F11: Covered | G11: P19
A12: 11 | B12: Health - Network-wide | C12: What is the fabric health status? | D12: PASS | F12: Gap - can automate | H12: ONES Fabric Manager (read)
A13: 12 | B13: Health - Network-wide | C13: Hardware SKU distribution across the network | D13: FAIL | E13: NCP-3721 | F13: Partly covered | G13: P05 | I13: Models are checked; counts per SKU are not. Manual FAIL.
A14: 13 | B14: Health - Network-wide | C14: Devices licensed vs. unlicensed | D14: PASS | F14: Gap - can automate | H14: ONES admin & licences
A15: 14 | B15: Health - Single Switch | C15: CPU and memory utilization on <IP> | D15: PASS | F15: Covered | G15: P09 | I15: ONES 10.4.4.181 returns no CPU / memory (null), so automation expects NCP to say 'not available' there.
A16: 15 | B16: Health - Single Switch | C16: Services up vs. down on <IP> | D16: PASS | F16: Gap - can automate | H16: ONES device detail
A17: 16 | B17: Health - Single Switch | C17: Which services use the most CPU on <IP>? | D17: FAIL | E17: NCP-3761 | F17: Gap - can automate | H17: ONES device detail
A18: 17 | B18: Health - Single Switch | C18: PSU health on <IP> | D18: PASS | F18: Partly covered | G18: P17 | I18: Checked for all devices; this switch-specific prompt is not asked.
A19: 18 | B19: Health - Single Switch | C19: Fan status on <IP> | D19: PASS | F19: Partly covered | G19: P17 | I19: Checked for all devices; this switch-specific prompt is not asked.
A20: 19 | B20: Health - Single Switch | C20: SSD health on <IP> | D20: PASS | F20: Gap - can automate | H20: ONES device detail
A21: 20 | B21: Health - Single Switch | C21: Transceiver info for Ethernet0 on <IP> | D21: PASS | F21: Gap - can automate | H21: ONES device detail
A22: 21 | B22: Bulk / Time-window | C22: Bulk health metrics for <IP> over the last 1 hour | D22: PASS | F22: Gap - can automate | H22: Time-window prompts
A23: 22 | B23: Bulk / Time-window | C23: CPU trend for <IP> over the last 4 hours | D23: FAIL | F23: Gap - can automate | H23: Time-window prompts
A24: 23 | B24: Bulk / Time-window | C24: Traffic counters for Ethernet0 on <IP> over the last 1 day | D24: PASS | F24: Partly covered | G24: P15 | I24: Snapshot counters only, not a 1-day window.
A25: 24 | B25: Inventory | C25: List all inventory devices | D25: PASS | F25: Covered | G25: P01
A26: 25 | B26: Inventory | C26: Show ports on switch <IP> | D26: PASS | F26: Covered | G26: P13
A27: 26 | B27: Inventory | C27: Show firmware version on <IP> | D27: PASS | F27: Partly covered | G27: P03 | I27: Software version for all devices is checked; firmware detail is not.
A28: 27 | B28: Inventory | C28: Show FAN/PSU inventory (parts, not health) for <IP> | D28: PASS | F28: Partly covered | G28: P17 | I28: Fan / PSU status is checked; the parts inventory is not.
A29: 28 | B29: Inventory | C29: Show devices with recent IP address changes | D29: PASS | F29: Gap - can automate | H29: ONES device detail
A30: 29 | B30: Inventory | C30: Show interface flaps on <IP> between two explicit UTC timestamps | D30: PASS | F30: Gap - can automate | H30: ONES device detail
A31: 30 | B31: Fabric Summaries | C31: Hardware summary for all fabrics | D31: FAIL | F31: Gap - can automate | H31: ONES Fabric Manager (read)
A32: 31 | B32: Fabric Summaries | C32: PSU + fan summary for Fabric 1 | D32: FAIL | F32: Partly covered | G32: P17 | I32: Fan / PSU checked for all devices, not per fabric. Manual FAIL.
A33: 32 | B33: Fabric Summaries | C33: Software versions across the fabric | D33: PASS | F33: Partly covered | G33: P04 | I33: OS versions checked for all devices, not per fabric.
A34: 33 | B34: Fabric Summaries | C34: Port + transceiver summary for Fabric 1 | D34: PASS | F34: Gap - can automate | H34: ONES device detail
A35: 34 | B35: Protocols & Routing | C35: Show BGP neighbors on <IP> | D35: PASS | F35: Gap - can automate | H35: ONES protocols & routing
A36: 35 | B36: Protocols & Routing | C36: BGP summary - neighbors up vs. down on <IP> | D36: PASS | F36: Gap - can automate | H36: ONES protocols & routing
A37: 36 | B37: Protocols & Routing | C37: Show VLANs on <IP> | D37: PASS | F37: Gap - can automate | H37: ONES protocols & routing
A38: 37 | B38: Protocols & Routing | C38: Show VxLAN summary on <IP> | D38: PASS | F38: Gap - can automate | H38: ONES protocols & routing
A39: 38 | B39: Protocols & Routing | C39: Show VxLAN VTEPs on <IP> | D39: PASS | F39: Gap - can automate | H39: ONES protocols & routing
A40: 39 | B40: Protocols & Routing | C40: Show MCLAG status on <IP> | D40: FAIL | F40: Gap - can automate | H40: ONES protocols & routing
...

Sheet Automation view
A1: ID | B1: Automated prompt (data/mcp_prompts.xlsx) | C1: Nexus Dashboard (Local MCP) - manual testcase No | D1: Catalyst Center (Local MCP) - manual testcase No | E1: Zabbix - manual testcase No | F1: ONES - manual testcase No
A2: P01 | B2: List all devices in my network. | C2: #18, #32, #57, #70 | D2: — | E2: #4 | F2: #1, #24
A3: P02 | B3: How many devices are in my network? | C3: #39, #77 | D3: — | E3: #78 | F3: —
A4: P03 | B4: List all devices with their hostname, management IP, model, serial number and software version. | C4: #38, #76 | D4: — | E4: #5, #6, #7, #8, #10, #76, #77, #79, #80, #81, #83 | F4: #26
A5: P04 | B5: How many devices are running each OS version? | C5: — | D5: — | E5: #7 | F5: #32
A6: P05 | B6: What are the different platforms / models running in the network? | C6: — | D6: — | E6: #5, #81 | F6: #12
A7: P06 | B7: Which devices look unhealthy? | C7: #19, #40, #58, #78 | D7: — | E7: #21, #91, #93 | F7: —
A8: P07 | B8: Show CPU utilization of all devices. | C8: #22, #33, #54, #61, #71 | D8: — | E8: #39, #106, #126 | F8: —
A9: P08 | B9: Show memory utilization of all devices. | C9: #22, #33, #54, #61, #71 | D9: — | E9: #40, #107 | F9: —
A10: P09 | B10: Show CPU and memory for device <DEVICE>. | C10: #23, #62 | D10: — | E10: #11, #12, #84, #85, #86, #92 | F10: #14
A11: P10 | B11: Which device currently has the highest CPU? | C11: #44, #82 | D11: — | E11: #39, #106 | F11: —
A12: P11 | B12: List devices with CPU utilization above 80%. | C12: — | D12: — | E12: — | F12: —
... A21: P20 | B21: Plot a bar chart of devices by OS version. | C21: — | D21: — | E21: — | F21: —
A23: Cells list the manual testcases (No in that connector's sheet) that this prompt covers fully or partly. '—' = no manual testcase asks this. Generic rows that say 'P01-P20' (Nexus #31, #52) are not counted here.

Sheet Gaps to add
A1: Priority | B1: Connector(s) | C1: Gap group | D1: What to add | E1: Manual testcases (No) | F1: Manual testcases | G1: Ground truth for the check | H1: Note
A2: High | B2: All 4 | C2: No credential / MCP-connection request | D2: Add a check to every answer: NCP must not ask for credentials or for an MCP connection. | E2: Nexus: #16, #17, #53 | F2: =COUNTIF(Nexus!$H$2:$H$90,$C2)+COUNTIF(Catalyst!$H$2:$H$26,$C2)+COUNTIF(Zabbix!$H$2:$H$127,$C2)+COUNTIF('ONES-MCP'!$H$2:$H$65,$C2) -> 3 | G2: None needed - a wording check on NCP's answer. | H2: Small change in checks.py / test_main.py.
A3: High | B3: All 4 | C3: Wrong-tag negative prompt | D3: Negative prompt: '#wrong-tag List all devices in my network.' - must not return that connector's devices. | E3: Nexus: #36, #74 | F3: =COUNTIF(Nexus!$H$2:$H$90,$C3)+COUNTIF(Catalyst!$H$2:$H$26,$C3)+COUNTIF(Zabbix!$H$2:$H$127,$C3)+COUNTIF('ONES-MCP'!$H$2:$H$65,$C3) -> 2 | G3: The connector's own device list (already read by the suite). | H3: One new check type.
A4: High | B4: Zabbix | C4: Zabbix problems | D4: Active problems: list, by severity, per host, host with most problems, high-severity check. | E4: Zabbix: #23, #24, #25, #27, #95, #96, #97, #98, #99 | F4: =COUNTIF(Nexus!$H$2:$H$90,$C4)+COUNTIF(Catalyst!$H$2:$H$26,$C4)+COUNTIF(Zabbix!$H$2:$H$127,$C4)+COUNTIF('ONES-MCP'!$H$2:$H$65,$C4) -> 9 | G4: Zabbix problem.get / trigger.get (truth/zabbix.py already calls trigger.get). | H4: Manual FAIL on #99 - worth automating first.
A5: High | B5: Zabbix | C5: Zabbix triggers | D5: Configured triggers on a host, memory triggers, disabled triggers, trigger count. | E5: Zabbix: #29, #30, #31, #100, #101 | F5: =COUNTIF(Nexus!$H$2:$H$90,$C5)+COUNTIF(Catalyst!$H$2:$H$26,$C5)+COUNTIF(Zabbix!$H$2:$H$127,$C5)+COUNTIF('ONES-MCP'!$H$2:$H$65,$C5) -> 5 | G5: Zabbix trigger.get. | H5: Manual FAIL on #101.
A6: Medium | B6: Zabbix | C6: Metric charts | D6: Charts: CPU, memory, temperature, fan, interface errors, problem timeline / pie, fleet ranking. | E6: Zabbix: #45, #46, #47, #48, #49, #50, #51, #52, #64, #110, #111, #112, #113, #114, #115, #117, #119, #125 | F6: =COUNTIF(Nexus!$H$2:$H$90,$C6)+COUNTIF(Catalyst!$H$2:$H$26,$C6)+COUNTIF(Zabbix!$H$2:$H$127,$C6)+COUNTIF('ONES-MCP'!$H$2:$H$65,$C6) -> 18 | G6: Same rule as P20: a chart is returned; any numbers in the text must match the source.
A7: Medium | B7: Nexus | C7: Nexus fabric prompts | D7: Fabric prompts: fabric summary, switches in a fabric, fabric interface overview. | E7: Nexus: #20, #21, #47, #59, #60, #86 | F7: =COUNTIF(Nexus!$H$2:$H$90,$C7)+COUNTIF(Catalyst!$H$2:$H$26,$C7)+COUNTIF(Zabbix!$H$2:$H$127,$C7)+COUNTIF('ONES-MCP'!$H$2:$H$65,$C7) -> 6 | G7: Nexus Dashboard fabric data - 10.20.11.3 runs in Fabric Discovery mode, fabric fields not confirmed.
A8: Medium | B8: ONES | C8: ONES device detail | D8: Transceivers, SSD health, services (up/down, CPU), IP changes, interface flaps, RoCE / advanced counters, port + transceiver summary. | E8: ONES-MCP: #15, #16, #19, #20, #28, #29, #33, #43, #44 | F8: =COUNTIF(Nexus!$H$2:$H$90,$C8)+COUNTIF(Catalyst!$H$2:$H$26,$C8)+COUNTIF(Zabbix!$H$2:$H$127,$C8)+COUNTIF('ONES-MCP'!$H$2:$H$65,$C8) -> 9 | G8: ONES REST per device. | H8: Manual FAIL on #16 and #43.
A9: Medium | B9: ONES | C9: ONES protocols & routing | D9: BGP neighbours and summary, VLANs, VxLAN summary / VTEPs, MCLAG, IPv4 routes, ACL use. | E9: ONES-MCP: #34, #35, #36, #37, #38, #39, #40, #41 | F9: =COUNTIF(Nexus!$H$2:$H$90,$C9)+COUNTIF(Catalyst!$H$2:$H$26,$C9)+COUNTIF(Zabbix!$H$2:$H$127,$C9)+COUNTIF('ONES-MCP'!$H$2:$H$65,$C9) -> 8 | G9: ONES REST - several routes return 404 / 500 on this build (CLAUDE.md §8). | H9: Manual FAIL on #39 (MCLAG).
A10: Medium | B10: Zabbix, ONES | C10: Time-window prompts | D10: Time-window prompts: min / avg / max over 5 min, 1 h, 24 h, 7 days, previous week; traffic on a port; CPU trend. | E10: Zabbix: #18, #26, #28, #38, #53, #54, #55, #56, #57, #58, #59, #60, #61, #105, #116, #118 ONES-MCP: #21, #22 | F10: =COUNTIF(Nexus!$H$2:$H$90,$C10)+COUNTIF(Catalyst!$H$2:$H$26,$C10)+COUNTIF(Zabbix!$H$2:$H$127,$C10)+COUNTIF('ONES-MCP'!$H$2:$H$65,$C10) -> 18 | G10: Zabbix history.get / trend.get; ONES bulk APIs (max 1-day window). | H10: Needs the truth pinned to the same window. Manual FAIL on ONES #22 and Zabbix #105.
A11: Medium | B11: Zabbix | C11: Zabbix vendors | D11: Vendors in the estate, vendor comparison. | E11: Zabbix: #9, #74, #82 | F11: =COUNTIF(Nexus!$H$2:$H$90,$C11)+COUNTIF(Catalyst!$H$2:$H$26,$C11)+COUNTIF(Zabbix!$H$2:$H$127,$C11)+COUNTIF('ONES-MCP'!$H$2:$H$65,$C11) -> 3 | G11: Zabbix host inventory (vendor field) - not confirmed.
A12: Medium | B12: Zabbix | C12: Zabbix extra items | D12: Uptime, disk use, fan speed, interface admin status / speed / duplex, fleet uptime. | E12: Zabbix: #16, #17, #34, #35, #43, #88 | F12: =COUNTIF(Nexus!$H$2:$H$90,$C12)+COUNTIF(Catalyst!$H$2:$H$26,$C12)+COUNTIF(Zabbix!$H$2:$H$127,$C12)+COUNTIF('ONES-MCP'!$H$2:$H$65,$C12) -> 6 | G12: Zabbix item.get - item keys not confirmed on 10.4.4.177 (check the probe snapshot).
A13: Low | B13: Zabbix | C13: Multi-part investigations | D13: Multi-part investigations (end-to-end host investigation, memory triage, compare two hosts). | E13: Zabbix: #120, #121, #122, #123, #124 | F13: =COUNTIF(Nexus!$H$2:$H$90,$C13)+COUNTIF(Catalyst!$H$2:$H$26,$C13)+COUNTIF(Zabbix!$H$2:$H$127,$C13)+COUNTIF('ONES-MCP'!$H$2:$H$65,$C13) -> 5 | G13: Split into the single checks above. | H13: Build after the single checks exist.
A14: Low | B14: Nexus | C14: Nexus anomalies / advisories | D14: Anomalies by severity / type, top anomalous nodes, advisories, anomaly vs advisory. | E14: Nexus: #29, #30, #41, #42, #43, #68, #69, #79, #80, #81 | F14: =COUNTIF(Nexus!$H$2:$H$90,$C14)+COUNTIF(Catalyst!$H$2:$H$26,$C14)+COUNTIF(Zabbix!$H$2:$H$127,$C14)+COUNTIF('ONES-MCP'!$H$2:$H$65,$C14) -> 10 | G14: Nexus Dashboard Insights APIs - not confirmed on 10.20.11.3.
A15: Low | B15: Nexus | C15: Nexus cluster prompts | D15: Cluster nodes, cluster resources, storage / disk summary. | E15: Nexus: #49, #50, #83, #88, #89 | F15: =COUNTIF(Nexus!$H$2:$H$90,$C15)+COUNTIF(Catalyst!$H$2:$H$26,$C15)+COUNTIF(Zabbix!$H$2:$H$127,$C15)+COUNTIF('ONES-MCP'!$H$2:$H$65,$C15) -> 5 | G15: Nexus Dashboard cluster APIs - not confirmed.
A16: Low | B16: ONES | C16: ONES admin & licences | D16: Installation ID, users, user roles, licences, licensed vs unlicensed devices. | E16: ONES-MCP: #4, #5, #13, #45, #46, #47 | F16: =COUNTIF(Nexus!$H$2:$H$90,$C16)+COUNTIF(Catalyst!$H$2:$H$26,$C16)+COUNTIF(Zabbix!$H$2:$H$127,$C16)+COUNTIF('ONES-MCP'!$H$2:$H$65,$C16) -> 6 | G16: ONES REST admin / licence routes.
A17: Low | B17: ONES | C17: ONES Fabric Manager (read) | D17: Fabrics count, fabric health, hardware summary per fabric, tenants (read only). | E17: ONES-MCP: #2, #11, #30, #48 | F17: =COUNTIF(Nexus!$H$2:$H$90,$C17)+COUNTIF(Catalyst!$H$2:$H$26,$C17)+COUNTIF(Zabbix!$H$2:$H$127,$C17)+COUNTIF('ONES-MCP'!$H$2:$H$65,$C17) -> 4 | G17: ONES Fabric Manager API - not set up in the suite. | H17: Manual FAIL on #30.
A18: Blocked | B18: ONES | C18: ONES alerts | D18: Alerts: last 24 h, per rule, per switch, alert payload. | E18: ONES-MCP: #3, #6, #7, #8, #9 | F18: =COUNTIF(Nexus!$H$2:$H$90,$C18)+COUNTIF(Catalyst!$H$2:$H$26,$C18)+COUNTIF(Zabbix!$H$2:$H$127,$C18)+COUNTIF('ONES-MCP'!$H$2:$H$65,$C18) -> 5 | G18: ONES alert APIs return 500 / empty on both hosts (CLAUDE.md §8) - no truth yet. | H18: Manual FAIL on #3, #6-#8 (NCP-3718 / NCP-3719).
A19: Blocked | B19: All 4 | C19: Project Chat | D19: Run every prompt in Project Chat too (house rule: PASS only if both chats pass). | E19: Nexus: #13 | F19: =COUNTIF(Nexus!$H$2:$H$90,$C19)+COUNTIF(Catalyst!$H$2:$H$26,$C19)+COUNTIF(Zabbix!$H$2:$H$127,$C19)+COUNTIF('ONES-MCP'!$H$2:$H$65,$C19) -> 1 | G19: Same as Admin Chat. | H19: Needs the WebSocket project_id field and a project (CLAUDE.md §11 q2, q3).
E20: Total gap testcases | F20: =SUM(F2:F19) -> 123
